<?xml version="1.0" ?>
<robot name="yumi">
    <link name="world" />
    <joint name="world_joint" type="fixed">
        <parent link="world" />
        <child link="yumi_body" />
        <origin xyz="0 0 0" rpy="0 0 0" />
    </joint>
    <joint name="yumi_joint_1_r" type="revolute">
        <parent link="yumi_body" />
        <child link="yumi_link_1_r" />
        <origin rpy="-0.9795 -0.5682 -2.3155" xyz="0.05355 -0.07249  0.51492" />
        <axis xyz="0  0  1" />
        <limit effort="300.0" lower="-2.9394" upper="2.9394" velocity="3.14" />
        <dynamics damping="0.5" />
    </joint>
    <joint name="yumi_joint_2_r" type="revolute">
        <parent link="yumi_link_1_r" />
        <child link="yumi_link_2_r" />
        <origin rpy="1.5707  0      0" xyz="0.03 0 0.1" />
        <axis xyz="0  0  1" />
        <limit effort="300.0" lower="-2.5033" upper="0.7588" velocity="3.14" />
        <dynamics damping="0.5" />
    </joint>
    <joint name="yumi_joint_7_r" type="revolute">
        <parent link="yumi_link_2_r" />
        <child link="yumi_link_3_r" />
        <origin rpy="-1.5707  0      0" xyz="-0.03 0.17283 0.0" />
        <axis xyz="0  0  1" />
        <limit effort="300.0" lower="-2.9394" upper="2.9394" velocity="3.14" />
        <dynamics damping="0.5" />
    </joint>
    <joint name="yumi_joint_3_r" type="revolute">
        <parent link="yumi_link_3_r" />
        <child link="yumi_link_4_r" />
        <origin rpy="1.5707  -1.5707 0" xyz="-0.04188 0.0 0.07873" />
        <axis xyz="0  0  1" />
        <limit effort="300.0" lower="-2.1544" upper="1.3956" velocity="3.14" />
        <dynamics damping="0.5" />
    </joint>
    <joint name="yumi_joint_4_r" type="revolute">
        <parent link="yumi_link_4_r" />
        <child link="yumi_link_5_r" />
        <origin xyz="0.0405 0.16461 0.0" rpy="-1.5707 0.0 0.0" />
        <axis xyz="0  0  1" />
        <limit effort="300.0" lower="-5.0589" upper="5.0589" velocity="6.98" />
        <dynamics damping="0.5" />
    </joint>
    <joint name="yumi_joint_5_r" type="revolute">
        <parent link="yumi_link_5_r" />
        <child link="yumi_link_6_r" />
        <origin xyz="-0.027 0 0.10039" rpy="1.5707 0.0 0.0" />
        <axis xyz="0  0  1" />
        <limit effort="300.0" lower="-1.5351" upper="2.4073" velocity="6.98" />
        <dynamics damping="0.5" />
    </joint>
    <joint name="yumi_joint_6_r" type="revolute">
        <parent link="yumi_link_6_r" />
        <child link="yumi_link_7_r" />
        <origin xyz="0.027 0.029 0.0" rpy="-1.5707 0.0 0.0" />
        <axis xyz="0  0  1" />
        <limit effort="300.0" lower="-3.9948" upper="3.9948" velocity="3.14" />
        <dynamics damping="0.5" />
    </joint>
    <joint name="yumi_joint_1_l" type="revolute">
        <parent link="yumi_body" />
        <child link="yumi_link_1_l" />
        <origin rpy="0.9781 -0.5716  2.318" xyz="0.05355  0.07249  0.51492" />
        <axis xyz="0  0  1" />
        <limit effort="300.0" lower="-2.9394" upper="2.9394" velocity="3.14" />
        <dynamics damping="0.5" />
    </joint>
    <joint name="yumi_joint_2_l" type="revolute">
        <parent link="yumi_link_1_l" />
        <child link="yumi_link_2_l" />
        <origin rpy="1.5707  0      0" xyz="0.03 0.0 0.1" />
        <axis xyz="0  0  1" />
        <limit effort="300.0" lower="-2.5033" upper="0.7588" velocity="3.14" />
        <dynamics damping="0.5" />
    </joint>
    <joint name="yumi_joint_7_l" type="revolute">
        <parent link="yumi_link_2_l" />
        <child link="yumi_link_3_l" />
        <origin rpy="-1.5707  0      0" xyz="-0.03 0.17283 0.0" />
        <axis xyz="0  0  1" />
        <limit effort="300.0" lower="-2.9394" upper="2.9394" velocity="3.14" />
        <dynamics damping="0.5" />
    </joint>
    <joint name="yumi_joint_3_l" type="revolute">
        <parent link="yumi_link_3_l" />
        <child link="yumi_link_4_l" />
        <origin rpy="1.5707  -1.5707      0" xyz="-0.04188 0.0 0.07873" />
        <axis xyz="0  0  1" />
        <limit effort="300.0" lower="-2.1544" upper="1.3956" velocity="3.14" />
        <dynamics damping="0.5" />
    </joint>
    <joint name="yumi_joint_4_l" type="revolute">
        <parent link="yumi_link_4_l" />
        <child link="yumi_link_5_l" />
        <origin rpy="-1.5707  0      0" xyz="0.0405   0.16461  0.0" />
        <axis xyz="0  0  1" />
        <limit effort="300.0" lower="-5.0589" upper="5.0589" velocity="6.98" />
        <dynamics damping="0.5" />
    </joint>
    <joint name="yumi_joint_5_l" type="revolute">
        <parent link="yumi_link_5_l" />
        <child link="yumi_link_6_l" />
        <origin rpy="1.5707  0      0" xyz="-0.027  0.0  0.10039" />
        <axis xyz="0  0  1" />
        <limit effort="300.0" lower="-1.5351" upper="2.4073" velocity="6.98" />
        <dynamics damping="0.5" />
    </joint>
    <joint name="yumi_joint_6_l" type="revolute">
        <parent link="yumi_link_6_l" />
        <child link="yumi_link_7_l" />
        <origin rpy="-1.5707  0      0" xyz="0.027 0.029 0.0" />
        <axis xyz="0  0  1" />
        <limit effort="300.0" lower="-3.9948" upper="3.9948" velocity="3.14" />
        <dynamics damping="0.5" />
    </joint>
    <!--LINKS-->
    <link name="yumi_body">
        <inertial>
            <mass value="15" />
            <origin rpy="0  0  0" xyz="0   0   0.1" />
            <inertia ixx="0.6" ixy="0" ixz="0" iyy="0.5" iyz="0" izz="0.3" />
        </inertial>
        <collision name="collision">
            <origin rpy="0  0  0" xyz="0   0   0.1" />
            <geometry>
                <mesh filename="package://yumi_description/meshes/coarse/body.stl" scale="1.0 1.0 1.0" />
            </geometry>
        </collision>
        <visual name="test">
            <origin rpy="0  0  0" xyz="0   0   0.1" />
            <geometry>
                <mesh filename="package://yumi_description/meshes/body.stl" scale="1.0 1.0 1.0" />
            </geometry>
        </visual>
    </link>
    <!--RIGHT ARM-->
    <link name="yumi_link_1_r">
        <inertial>
            <mass value="1" />
            <origin rpy="0  0  0" xyz="0  0  0" />
            <inertia ixx="0.1" ixy="0" ixz="0" iyy="0.1" iyz="0" izz="0.1" />
        </inertial>
        <collision name="collision">
            <origin rpy="0  0  0" xyz="0  0  0" />
            <geometry>
                <mesh filename="package://yumi_description/meshes/coarse/link_1.stl" scale="1.0 1.0 1.0" />
            </geometry>
        </collision>
        <visual name="yumi_link1">
            <origin rpy="0  0  0" xyz="0  0  0" />
            <geometry>
                <mesh filename="package://yumi_description/meshes/link_1.stl" scale="1.0 1.0 1.0" />
            </geometry>
        </visual>
    </link>
    <link name="yumi_link_2_r">
        <inertial>
            <mass value="1" />
            <origin rpy="0  0  0" xyz="0  0  0" />
            <inertia ixx="0.1" ixy="0" ixz="0" iyy="0.1" iyz="0" izz="0.1" />
        </inertial>
        <collision name="collision">
            <origin rpy="0  0  0" xyz="0  0  0" />
            <geometry>
                <mesh filename="package://yumi_description/meshes/coarse/link_2.stl" scale="1.0 1.0 1.0" />
            </geometry>
        </collision>
        <visual name="yumi_link2">
            <origin rpy="0  0  0" xyz="0  0  0" />
            <geometry>
                <mesh filename="package://yumi_description/meshes/link_2.stl" scale="1.0 1.0 1.0" />
            </geometry>
        </visual>
    </link>
    <link name="yumi_link_3_r">
        <inertial>
            <mass value="1" />
            <origin rpy="0  0  0" xyz="0  0  0" />
            <inertia ixx="0.1" ixy="0" ixz="0" iyy="0.1" iyz="0" izz="0.1" />
        </inertial>
        <collision name="collision">
            <origin rpy="0  0  0" xyz="0  0  0" />
            <geometry>
                <mesh filename="package://yumi_description/meshes/coarse/link_3.stl" scale="1.0 1.0 1.0" />
            </geometry>
        </collision>
        <visual name="yumi_link3">
            <origin rpy="0  0  0" xyz="0  0  0" />
            <geometry>
                <mesh filename="package://yumi_description/meshes/link_3.stl" scale="1.0 1.0 1.0" />
            </geometry>
        </visual>
    </link>
    <link name="yumi_link_4_r">
        <inertial>
            <mass value="1" />
            <origin rpy="0  0  0" xyz="0  0  0" />
            <inertia ixx="0.1" ixy="0" ixz="0" iyy="0.1" iyz="0" izz="0.1" />
        </inertial>
        <collision name="collision">
            <origin rpy="0  0  0" xyz="0  0  0" />
            <geometry>
                <mesh filename="package://yumi_description/meshes/coarse/link_4.stl" scale="1.0 1.0 1.0" />
            </geometry>
        </collision>
        <visual name="yumi_link4">
            <origin rpy="0  0  0" xyz="0  0  0" />
            <geometry>
                <mesh filename="package://yumi_description/meshes/link_4.stl" scale="1.0 1.0 1.0" />
            </geometry>
        </visual>
    </link>
    <link name="yumi_link_5_r">
        <inertial>
            <mass value="1" />
            <origin rpy="0  0  0" xyz="0  0  0" />
            <inertia ixx="0.1" ixy="0" ixz="0" iyy="0.1" iyz="0" izz="0.1" />
        </inertial>
        <collision name="collision">
            <origin rpy="0  0  0" xyz="0  0  0" />
            <geometry>
                <mesh filename="package://yumi_description/meshes/coarse/link_5.stl" scale="1.0 1.0 1.0" />
            </geometry>
        </collision>
        <visual name="yumi_link5">
            <origin rpy="0  0  0" xyz="0  0  0" />
            <geometry>
                <mesh filename="package://yumi_description/meshes/link_5.stl" scale="1.0 1.0 1.0" />
            </geometry>
        </visual>
    </link>
    <link name="yumi_link_6_r">
        <inertial>
            <mass value="1" />
            <origin rpy="0  0  0" xyz="0  0  0" />
            <inertia ixx="0.1" ixy="0" ixz="0" iyy="0.1" iyz="0" izz="0.1" />
        </inertial>
        <collision name="collision">
            <origin rpy="0  0  0" xyz="0  0  0" />
            <geometry>
                <mesh filename="package://yumi_description/meshes/coarse/link_6.stl" scale="1.0 1.0 1.0" />
            </geometry>
        </collision>
        <visual name="yumi_link5">
            <origin rpy="0  0  0" xyz="0  0  0" />
            <geometry>
                <mesh filename="package://yumi_description/meshes/link_6.stl" scale="1.0 1.0 1.0" />
            </geometry>
        </visual>
    </link>
    <link name="yumi_link_7_r">
        <inertial>
            <mass value="1" />
            <origin rpy="0  0  0" xyz="0  0  0" />
            <inertia ixx="0.1" ixy="0" ixz="0" iyy="0.1" iyz="0" izz="0.1" />
        </inertial>
        <collision name="collision">
            <origin rpy="0  0  0" xyz="0  0  0" />
            <geometry>
                <mesh filename="package://yumi_description/meshes/coarse/link_7.stl" scale="1.0 1.0 1.0" />
            </geometry>
        </collision>
        <visual name="yumi_link7">
            <origin rpy="0  0  0" xyz="0  0  0" />
            <geometry>
                <mesh filename="package://yumi_description/meshes/link_7.stl" scale="1.0 1.0 1.0" />
            </geometry>
        </visual>
    </link>
    <!--LEFT ARM-->
    <link name="yumi_link_1_l">
        <inertial>
            <mass value="1" />
            <origin rpy="0  0  0" xyz="0  0  0" />
            <inertia ixx="0.1" ixy="0" ixz="0" iyy="0.1" iyz="0" izz="0.1" />
        </inertial>
        <collision name="collision">
            <origin rpy="0  0  0" xyz="0  0  0" />
            <geometry>
                <mesh filename="package://yumi_description/meshes/coarse/link_1.stl" scale="1.0 1.0 1.0" />
            </geometry>
        </collision>
        <visual name="yumi_link1l">
            <origin rpy="0  0  0" xyz="0  0  0" />
            <geometry>
                <mesh filename="package://yumi_description/meshes/link_1.stl" scale="1.0 1.0 1.0" />
            </geometry>
        </visual>
    </link>
    <link name="yumi_link_2_l">
        <inertial>
            <mass value="1" />
            <origin rpy="0  0  0" xyz="0  0  0" />
            <inertia ixx="0.1" ixy="0" ixz="0" iyy="0.1" iyz="0" izz="0.1" />
        </inertial>
        <collision name="collision">
            <origin rpy="0  0  0" xyz="0  0  0" />
            <geometry>
                <mesh filename="package://yumi_description/meshes/coarse/link_2.stl" scale="1.0 1.0 1.0" />
            </geometry>
        </collision>
        <visual name="yumi_link2">
            <origin rpy="0  0  0" xyz="0  0  0" />
            <geometry>
                <mesh filename="package://yumi_description/meshes/link_2.stl" scale="1.0 1.0 1.0" />
            </geometry>
        </visual>
    </link>
    <link name="yumi_link_3_l">
        <inertial>
            <mass value="1" />
            <origin rpy="0  0  0" xyz="0  0  0" />
            <inertia ixx="0.1" ixy="0" ixz="0" iyy="0.1" iyz="0" izz="0.1" />
        </inertial>
        <collision name="collision">
            <origin rpy="0  0  0" xyz="0  0  0" />
            <geometry>
                <mesh filename="package://yumi_description/meshes/coarse/link_3.stl" scale="1.0 1.0 1.0" />
            </geometry>
        </collision>
        <visual name="yumi_link3">
            <origin rpy="0  0  0" xyz="0  0  0" />
            <geometry>
                <mesh filename="package://yumi_description/meshes/link_3.stl" scale="1.0 1.0 1.0" />
            </geometry>
        </visual>
    </link>
    <link name="yumi_link_4_l">
        <inertial>
            <mass value="1" />
            <origin rpy="0  0  0" xyz="0  0  0" />
            <inertia ixx="0.1" ixy="0" ixz="0" iyy="0.1" iyz="0" izz="0.1" />
        </inertial>
        <collision name="collision">
            <origin rpy="0  0  0" xyz="0  0  0" />
            <geometry>
                <mesh filename="package://yumi_description/meshes/coarse/link_4.stl" scale="1.0 1.0 1.0" />
            </geometry>
        </collision>
        <visual name="yumi_link4">
            <origin rpy="0  0  0" xyz="0  0  0" />
            <geometry>
                <mesh filename="package://yumi_description/meshes/link_4.stl" scale="1.0 1.0 1.0" />
            </geometry>
        </visual>
    </link>
    <link name="yumi_link_5_l">
        <inertial>
            <mass value="1" />
            <origin rpy="0  0  0" xyz="0  0  0" />
            <inertia ixx="0.1" ixy="0" ixz="0" iyy="0.1" iyz="0" izz="0.1" />
        </inertial>
        <collision name="collision">
            <origin rpy="0  0  0" xyz="0  0  0" />
            <geometry>
                <mesh filename="package://yumi_description/meshes/coarse/link_5.stl" scale="1.0 1.0 1.0" />
            </geometry>
        </collision>
        <visual name="yumi_link5">
            <origin rpy="0  0  0" xyz="0  0  0" />
            <geometry>
                <mesh filename="package://yumi_description/meshes/link_5.stl" scale="1.0 1.0 1.0" />
            </geometry>
        </visual>
    </link>
    <link name="yumi_link_6_l">
        <inertial>
            <mass value="1" />
            <origin rpy="0  0  0" xyz="0  0  0" />
            <inertia ixx="0.1" ixy="0" ixz="0" iyy="0.1" iyz="0" izz="0.1" />
        </inertial>
        <collision name="collision">
            <origin rpy="0  0  0" xyz="0  0  0" />
            <geometry>
                <mesh filename="package://yumi_description/meshes/coarse/link_6.stl" scale="1.0 1.0 1.0" />
            </geometry>
        </collision>
        <visual name="yumi_link5">
            <origin rpy="0  0  0" xyz="0  0  0" />
            <geometry>
                <mesh filename="package://yumi_description/meshes/link_6.stl" scale="1.0 1.0 1.0" />
            </geometry>
        </visual>
    </link>
    <link name="yumi_link_7_l">
        <inertial>
            <mass value="1" />
            <origin rpy="0  0  0" xyz="0  0  0" />
            <inertia ixx="0.1" ixy="0" ixz="0" iyy="0.1" iyz="0" izz="0.1" />
        </inertial>
        <collision name="collision">
            <origin rpy="0  0  0" xyz="0  0  0" />
            <geometry>
                <mesh filename="package://yumi_description/meshes/coarse/link_7.stl" scale="1.0 1.0 1.0" />
            </geometry>
        </collision>
        <visual name="yumi_link7">
            <origin rpy="0  0  0" xyz="0  0  0" />
            <geometry>
                <mesh filename="package://yumi_description/meshes/link_7.stl" scale="1.0 1.0 1.0" />
            </geometry>
        </visual>
    </link>
    <!--LEFT GRIPPER BASE-->
    <joint name="yumi_joint_8_l" type="fixed">
        <parent link="yumi_link_7_l" />
        <child link="gripper_l_base" />
        <origin rpy="0  0  3.1416" xyz="0 0 0.007" />
    </joint>
    <link name="gripper_l_base">
        <inertial>
            <origin xyz="0 0 0" rpy="0 0 0" />
            <mass value="0.2" />
            <inertia ixx="0.0001" ixy="0" ixz="0" iyy="0.0001" iyz="0" izz="0.0001" />
        </inertial>
        <visual>
            <origin xyz="0 0 0" rpy="0 0 0" />
            <geometry>
                <mesh filename="package://yumi_description/meshes/gripper/base.stl" />
            </geometry>
        </visual>
        <collision>
            <origin xyz="0 0 0" rpy="0 0 0" />
            <geometry>
                <mesh filename="package://yumi_description/meshes/gripper/coarse/base.stl" />
            </geometry>
        </collision>
    </link>
    <!--LEFT GRIPPER FINGERS-->
    <joint name="yumi_joint_gripper_l_finger_r" type="prismatic">
        <parent link="gripper_l_base" />
        <child link="gripper_l_finger_r" />
        <origin xyz="0 -0.0065 0.0837" rpy="0 0 0" />
        <axis xyz="-1 0 0" />
        <limit lower="0" upper="0.025" effort="300" velocity="0.02" />
        <dynamics damping="0.5" />
    </joint>
    <link name="gripper_l_finger_r">
        <inertial>
            <origin xyz="0 0 0" rpy="0 0 0" />
            <mass value="0.01" />
            <inertia ixx="0.000001" ixy="0" ixz="0" iyy="0.000001" iyz="0" izz="0.000001" />
        </inertial>
        <visual>
            <origin xyz="0 0 0" rpy="0 0 0" />
            <geometry>
                <mesh filename="package://yumi_description/meshes/gripper/finger.stl" />
            </geometry>
        </visual>
        <collision>
            <origin xyz="0 0 0" rpy="0 0 0" />
            <geometry>
                <mesh filename="package://yumi_description/meshes/gripper/coarse/finger.stl" />
            </geometry>
        </collision>
    </link>
    <joint name="yumi_joint_gripper_l_finger_l" type="prismatic">
        <parent link="gripper_l_base" />
        <child link="gripper_l_finger_l" />
        <origin xyz="0 0.0065 0.0837" rpy="0 0 3.1416" />
        <axis xyz="-1 0 0" />
        <limit lower="0" upper="0.025" effort="300" velocity="0.02" />
        <dynamics damping="0.5" />
        <mimic joint="yumi_joint_gripper_l_finger_r" />
    </joint>
    <link name="gripper_l_finger_l">
        <inertial>
            <origin xyz="0 0 0" rpy="0 0 0" />
            <mass value="0.01" />
            <inertia ixx="0.000001" ixy="0" ixz="0" iyy="0.000001" iyz="0" izz="0.000001" />
        </inertial>
        <visual>
            <origin xyz="0 0 0" rpy="0 0 0" />
            <geometry>
                <mesh filename="package://yumi_description/meshes/gripper/finger.stl" />
            </geometry>
        </visual>
        <collision>
            <origin xyz="0 0 0" rpy="0 0 0" />
            <geometry>
                <mesh filename="package://yumi_description/meshes/gripper/coarse/finger.stl" />
            </geometry>
        </collision>
    </link>
    <!--RIGHT GRIPPER BASE-->
    <joint name="yumi_joint_8_r" type="fixed">
        <parent link="yumi_link_7_r" />
        <child link="gripper_r_base" />
        <origin rpy="0  0  3.1416" xyz="0 0 0.007" />
    </joint>
    <link name="gripper_r_base">
        <inertial>
            <origin xyz="0 0 0" rpy="0 0 0" />
            <mass value="0.2" />
            <inertia ixx="0.0001" ixy="0" ixz="0" iyy="0.0001" iyz="0" izz="0.0001" />
        </inertial>
        <visual>
            <origin xyz="0 0 0" rpy="0 0 0" />
            <geometry>
                <mesh filename="package://yumi_description/meshes/gripper/base.stl" />
            </geometry>
        </visual>
        <collision>
            <origin xyz="0 0 0" rpy="0 0 0" />
            <geometry>
                <mesh filename="package://yumi_description/meshes/gripper/coarse/base.stl" />
            </geometry>
        </collision>
    </link>
    <!--LEFT GRIPPER FINGERS-->
    <joint name="yumi_joint_gripper_r_finger_r" type="prismatic">
        <parent link="gripper_r_base" />
        <child link="gripper_r_finger_r" />
        <origin xyz="0 -0.0065 0.0837" rpy="0 0 0" />
        <axis xyz="-1 0 0" />
        <limit lower="0" upper="0.025" effort="300" velocity="0.02" />
        <dynamics damping="0.5" />
    </joint>
    <link name="gripper_r_finger_r">
        <inertial>
            <origin xyz="0 0 0" rpy="0 0 0" />
            <mass value="0.01" />
            <inertia ixx="0.000001" ixy="0" ixz="0" iyy="0.000001" iyz="0" izz="0.000001" />
        </inertial>
        <visual>
            <origin xyz="0 0 0" rpy="0 0 0" />
            <geometry>
                <mesh filename="package://yumi_description/meshes/gripper/finger.stl" />
            </geometry>
        </visual>
        <collision>
            <origin xyz="0 0 0" rpy="0 0 0" />
            <geometry>
                <mesh filename="package://yumi_description/meshes/gripper/coarse/finger.stl" />
            </geometry>
        </collision>
    </link>
    <joint name="yumi_joint_gripper_r_finger_l" type="prismatic">
        <parent link="gripper_r_base" />
        <child link="gripper_r_finger_l" />
        <origin xyz="0 0.0065 0.0837" rpy="0 0 3.1416" />
        <axis xyz="-1 0 0" />
        <limit lower="0" upper="0.025" effort="300" velocity="0.02" />
        <dynamics damping="0.5" />
        <mimic joint="yumi_joint_gripper_r_finger_r" />
    </joint>
    <link name="gripper_r_finger_l">
        <inertial>
            <origin xyz="0 0 0" rpy="0 0 0" />
            <mass value="0.01" />
            <inertia ixx="0.000001" ixy="0" ixz="0" iyy="0.000001" iyz="0" izz="0.000001" />
        </inertial>
        <visual>
            <origin xyz="0 0 0" rpy="0 0 0" />
            <geometry>
                <mesh filename="package://yumi_description/meshes/gripper/finger.stl" />
            </geometry>
        </visual>
        <collision>
            <origin xyz="0 0 0" rpy="0 0 0" />
            <geometry>
                <mesh filename="package://yumi_description/meshes/gripper/coarse/finger.stl" />
            </geometry>
        </collision>
    </link>
    <!--TRANSMISSIONS FOR ARM LINKS-->
    <transmission name="tran_1_r">
        <type>transmission_interface/SimpleTransmission</type>
        <joint name="yumi_joint_1_r">
            <hardwareInterface>PositionJointInterface</hardwareInterface>
        </joint>
        <actuator name="motor_1_r">
            <mechanicalReduction>1</mechanicalReduction>
            <hardwareInterface>PositionJointInterface</hardwareInterface>
        </actuator>
    </transmission>
    <transmission name="tran_2_r">
        <type>transmission_interface/SimpleTransmission</type>
        <joint name="yumi_joint_2_r">
            <hardwareInterface>PositionJointInterface</hardwareInterface>
        </joint>
        <actuator name="motor_2_r">
            <mechanicalReduction>1</mechanicalReduction>
            <hardwareInterface>PositionJointInterface</hardwareInterface>
        </actuator>
    </transmission>
    <transmission name="tran_7_r">
        <type>transmission_interface/SimpleTransmission</type>
        <joint name="yumi_joint_7_r">
            <hardwareInterface>PositionJointInterface</hardwareInterface>
        </joint>
        <actuator name="motor_7_r">
            <mechanicalReduction>1</mechanicalReduction>
            <hardwareInterface>PositionJointInterface</hardwareInterface>
        </actuator>
    </transmission>
    <transmission name="tran_3_r">
        <type>transmission_interface/SimpleTransmission</type>
        <joint name="yumi_joint_3_r">
            <hardwareInterface>PositionJointInterface</hardwareInterface>
        </joint>
        <actuator name="motor_3_r">
            <mechanicalReduction>1</mechanicalReduction>
            <hardwareInterface>PositionJointInterface</hardwareInterface>
        </actuator>
    </transmission>
    <transmission name="tran_4_r">
        <type>transmission_interface/SimpleTransmission</type>
        <joint name="yumi_joint_4_r">
            <hardwareInterface>PositionJointInterface</hardwareInterface>
        </joint>
        <actuator name="motor_4_r">
            <mechanicalReduction>1</mechanicalReduction>
            <hardwareInterface>PositionJointInterface</hardwareInterface>
        </actuator>
    </transmission>
    <transmission name="tran_5_r">
        <type>transmission_interface/SimpleTransmission</type>
        <joint name="yumi_joint_5_r">
            <hardwareInterface>PositionJointInterface</hardwareInterface>
        </joint>
        <actuator name="motor_5_r">
            <mechanicalReduction>1</mechanicalReduction>
            <hardwareInterface>PositionJointInterface</hardwareInterface>
        </actuator>
    </transmission>
    <transmission name="tran_6_r">
        <type>transmission_interface/SimpleTransmission</type>
        <joint name="yumi_joint_6_r">
            <hardwareInterface>PositionJointInterface</hardwareInterface>
        </joint>
        <actuator name="motor_6_r">
            <mechanicalReduction>1</mechanicalReduction>
            <hardwareInterface>PositionJointInterface</hardwareInterface>
        </actuator>
    </transmission>
    <transmission name="tran_1_l">
        <type>transmission_interface/SimpleTransmission</type>
        <joint name="yumi_joint_1_l">
            <hardwareInterface>PositionJointInterface</hardwareInterface>
        </joint>
        <actuator name="motor_1_l">
            <mechanicalReduction>1</mechanicalReduction>
            <hardwareInterface>PositionJointInterface</hardwareInterface>
        </actuator>
    </transmission>
    <transmission name="tran_2_l">
        <type>transmission_interface/SimpleTransmission</type>
        <joint name="yumi_joint_2_l">
            <hardwareInterface>PositionJointInterface</hardwareInterface>
        </joint>
        <actuator name="motor_2_l">
            <mechanicalReduction>1</mechanicalReduction>
            <hardwareInterface>PositionJointInterface</hardwareInterface>
        </actuator>
    </transmission>
    <transmission name="tran_7_l">
        <type>transmission_interface/SimpleTransmission</type>
        <joint name="yumi_joint_7_l">
            <hardwareInterface>PositionJointInterface</hardwareInterface>
        </joint>
        <actuator name="motor_7_l">
            <mechanicalReduction>1</mechanicalReduction>
            <hardwareInterface>PositionJointInterface</hardwareInterface>
        </actuator>
    </transmission>
    <transmission name="tran_3_l">
        <type>transmission_interface/SimpleTransmission</type>
        <joint name="yumi_joint_3_l">
            <hardwareInterface>PositionJointInterface</hardwareInterface>
        </joint>
        <actuator name="motor_3_l">
            <mechanicalReduction>1</mechanicalReduction>
            <hardwareInterface>PositionJointInterface</hardwareInterface>
        </actuator>
    </transmission>
    <transmission name="tran_4_l">
        <type>transmission_interface/SimpleTransmission</type>
        <joint name="yumi_joint_4_l">
            <hardwareInterface>PositionJointInterface</hardwareInterface>
        </joint>
        <actuator name="motor_4_l">
            <mechanicalReduction>1</mechanicalReduction>
            <hardwareInterface>PositionJointInterface</hardwareInterface>
        </actuator>
    </transmission>
    <transmission name="tran_5_l">
        <type>transmission_interface/SimpleTransmission</type>
        <joint name="yumi_joint_5_l">
            <hardwareInterface>PositionJointInterface</hardwareInterface>
        </joint>
        <actuator name="motor_5_l">
            <mechanicalReduction>1</mechanicalReduction>
            <hardwareInterface>PositionJointInterface</hardwareInterface>
        </actuator>
    </transmission>
    <transmission name="tran_6_l">
        <type>transmission_interface/SimpleTransmission</type>
        <joint name="yumi_joint_6_l">
            <hardwareInterface>PositionJointInterface</hardwareInterface>
        </joint>
        <actuator name="motor_6_l">
            <mechanicalReduction>1</mechanicalReduction>
            <hardwareInterface>PositionJointInterface</hardwareInterface>
        </actuator>
    </transmission>
    <transmission name="tran_gripper_l">
        <type>transmission_interface/SimpleTransmission</type>
        <joint name="yumi_joint_gripper_l_finger_r">
            <hardwareInterface>PositionJointInterface</hardwareInterface>
        </joint>
        <actuator name="motor_8_l">
            <mechanicalReduction>1</mechanicalReduction>
            <hardwareInterface>PositionJointInterface</hardwareInterface>
        </actuator>
    </transmission>
    <transmission name="tran_gripper_r">
        <type>transmission_interface/SimpleTransmission</type>
        <joint name="yumi_joint_gripper_r_finger_r">
            <hardwareInterface>PositionJointInterface</hardwareInterface>
        </joint>
        <actuator name="motor_8_r">
            <mechanicalReduction>1</mechanicalReduction>
            <hardwareInterface>PositionJointInterface</hardwareInterface>
        </actuator>
    </transmission>
    <gazebo>
        <plugin name="gazebo_ros_control" filename="libgazebo_ros_control.so">
            <robotNamespace>/yumi</robotNamespace>
        </plugin>
    </gazebo>
    <transmission name="trans_yumi_joint_gripper_l_finger_l">
        <type>transmission_interface/SimpleTransmission</type>
        <joint name="yumi_joint_gripper_l_finger_l">
            <hardwareInterface>hardware_interface/EffortJointInterface</hardwareInterface>
        </joint>
        <actuator name="yumi_joint_gripper_l_finger_l_motor">
            <hardwareInterface>hardware_interface/EffortJointInterface</hardwareInterface>
            <mechanicalReduction>1</mechanicalReduction>
        </actuator>
    </transmission>
    <transmission name="trans_yumi_joint_gripper_r_finger_l">
        <type>transmission_interface/SimpleTransmission</type>
        <joint name="yumi_joint_gripper_r_finger_l">
            <hardwareInterface>hardware_interface/EffortJointInterface</hardwareInterface>
        </joint>
        <actuator name="yumi_joint_gripper_r_finger_l_motor">
            <hardwareInterface>hardware_interface/EffortJointInterface</hardwareInterface>
            <mechanicalReduction>1</mechanicalReduction>
        </actuator>
    </transmission>
</robot>

